<?xml version="1.0"?>
<robot name="krever">
   
<!--colors-->
    <material name="green">
        <color rgba="0 1 0 1"/>
    </material>

    <material name="blue">
        <color rgba="0 0 0.7 1"/>
    </material>

    <material name="red">
        <color rgba="0.7 0 0 1"/>
    </material>
     
    
    <link name="base_footprint">
        <inertial>
            <mass value="1.0"/> <!-- Adjust the mass as per your robot -->
            <inertia ixx="0.1" ixy="0.0" ixz="0.0" iyy="0.1" iyz="0.0" izz="0.1"/>
        </inertial>
    </link>


<!--base chassis-->
    <link name="base_link">
        <visual>
            <geometry>
                <box size="0.8 0.6 0.3"/>
            </geometry>
            <origin xyz="0 0 0.15" rpy="0 0 0"/>
            <material name="red"/>
        </visual>

        <collision>
            <geometry>
                <box size="0.6 0.8 0.3"/>
            </geometry>
            <origin xyz="0 0 0.15" rpy="0 0 0"/>
            <material name="red"/>
        </collision>

        <!-- Inertial block -->
        <inertial>
            <mass value="5.0"/>
            <origin xyz="0 0 0.15" rpy="0 0 0"/>
            <inertia>
                <!-- Inertia matrix calculated for a box -->
                <ixx value="0.075"/>
                <iyy value="0.133"/>
                <izz value="0.187"/>
                <ixy value="0"/>
                <ixz value="0"/>
                <iyz value="0"/>
            </inertia>
        </inertial>
    </link>

    <joint name="base_joint" type="fixed">
        <parent link="base_footprint"/>
        <child link="base_link"/>
        <origin xyz="0 0 0.1" rpy="0 0 0"/>
    </joint>



<!--lidar-->
    <link name="lidar">
        <visual>
            <geometry>
                <cylinder radius="0.1" length="0.05"/>
            </geometry>
            <origin xyz="0 0 0" rpy="0 0 0"/>
            <material name="blue"/>
        </visual>
        <collision>
            <geometry>
                <cylinder radius="0.1" length="0.05"/>
            </geometry>
            <origin xyz="0 0 0" rpy="0 0 0"/>
            <material name="blue"/>
        </collision>

        <inertial>
            <mass value="0.1"/> <!-- Mass of the lidar -->
            <origin xyz="0 0 0" rpy="0 0 0"/> <!-- Origin of the inertial frame -->
            <inertia>
                <ixx value="0.000042"/> <!-- Inertia about the x-axis -->
                <iyy value="0.000042"/> <!-- Inertia about the y-axis -->
                <izz value="0.0000017"/> <!-- Inertia about the z-axis -->
                <ixy value="0.0"/>      <!-- Product of inertia xy -->
                <ixz value="0.0"/>      <!-- Product of inertia xz -->
                <iyz value="0.0"/>      <!-- Product of inertia yz -->
            </inertia>
        </inertial>
    </link>

    <joint name="base_lidar_joint" type="fixed">
        <parent link="base_link"/>
        <child link="lidar"/>
        <origin xyz="0 0 0.325" rpy="0 0 0"/>
    </joint>


<!-- left wheel-->
    <link name="left_wheel">
        <visual>
            <geometry>
                <cylinder radius="0.1" length="0.05"/>
            </geometry>
            <origin xyz="0 0 0" rpy="1.57 0 0"/>
            <material name="green"/>
        </visual>
        <collision>
            <geometry>
                <cylinder radius="0.1" length="0.05"/>
            </geometry>
            <origin xyz="0 0 0" rpy="1.57 0 0"/>
            <material name="green"/>
        </collision>

        <inertial>
            <mass value="0.1"/> <!-- Mass of the wheel -->
            <origin xyz="0 0 0" rpy="1.57 0 0"/> <!-- Origin of the inertial frame -->
            <inertia>
                <ixx value="0.000042"/> <!-- Inertia about the x-axis -->
                <iyy value="0.000042"/> <!-- Inertia about the y-axis -->
                <izz value="0.0000017"/> <!-- Inertia about the z-axis -->
                <ixy value="0.0"/>      <!-- Product of inertia xy -->
                <ixz value="0.0"/>      <!-- Product of inertia xz -->
                <iyz value="0.0"/>      <!-- Product of inertia yz -->
            </inertia>
        </inertial>
    </link>

    <joint name="base_left_wheel_joint" type="continuous">
    <parent link="base_link"/>
        <child link="left_wheel"/>
        <origin xyz="0 0.325 0" rpy="0 0 0"/>
        <axis xyz="0 1 0"/>
    </joint>


<!--right wheel-->
    <link name="right_wheel">
        <visual>
            <geometry>
                <cylinder radius="0.1" length="0.05"/>
            </geometry>
            <origin xyz="0 0 0" rpy="1.57 0 0"/>
            <material name="green"/>
        </visual>
        <collision>
            <geometry>
                <cylinder radius="0.1" length="0.05"/>
            </geometry>
            <origin xyz="0 0 0" rpy="1.57 0 0"/>
            <material name="green"/>
        </collision>

        <inertial>
            <mass value="0.1"/> <!-- Mass of the wheel -->
            <origin xyz="0 0 0" rpy="1.57 0 0"/> <!-- Origin of the inertial frame -->
            <inertia>
                <ixx value="0.000042"/> <!-- Inertia about the x-axis -->
                <iyy value="0.000042"/> <!-- Inertia about the y-axis -->
                <izz value="0.0000017"/> <!-- Inertia about the z-axis -->
                <ixy value="0.0"/>      <!-- Product of inertia xy -->
                <ixz value="0.0"/>      <!-- Product of inertia xz -->
                <iyz value="0.0"/>      <!-- Product of inertia yz -->
            </inertia>
        </inertial>
    </link>

    <joint name="base_right_wheel_joint" type="continuous">
        <parent link="base_link"/>
        <child link="right_wheel"/>
        <origin xyz="-0 -0.325 0" rpy="0 0 0"/>
        <axis xyz="0 1 0"/>
    </joint>

<!-- caster wheel1 -->
    <link name="caster_wheel1">
        <visual>
            <geometry>
                <sphere radius="0.05"/>
            </geometry>
            <origin xyz="0 0 0" rpy="1.57 0 0"/>
            <material name="blue"/>
        </visual>
        <collision>
            <geometry>
                <sphere radius="0.05"/>
            </geometry>
            <origin xyz="0 0 0" rpy="1.57 0 0"/>
            <material name="blue"/>
        </collision>

        <inertial>
            <mass value="0.08"/> <!-- Mass of the caster wheel -->
            <origin xyz="0 0 0" rpy="0 0 0"/> <!-- Origin of the inertial frame -->
            <inertia>
                <ixx value="0.0000001"/> <!-- Inertia about the x-axis -->
                <iyy value="0.0000001"/> <!-- Inertia about the y-axis -->
                <izz value="0.00000024"/> <!-- Inertia about the z-axis -->
                <ixy value="0.0"/>      <!-- Product of inertia xy -->
                <ixz value="0.0"/>      <!-- Product of inertia xz -->
                <iyz value="0.0"/>      <!-- Product of inertia yz -->
            </inertia>
    </inertial>
    </link>
    
    <joint name="body_caster_wheel_joint1" type="fixed">
        <parent link="base_link"/>
        <child link="caster_wheel1"/>
        <origin xyz="0.3 0 -0.05" rpy="0 0 0"/>
    </joint>

<!-- caster wheel2 -->
    <link name="caster_wheel2">
        <visual>
            <geometry>
                <sphere radius="0.05"/>
            </geometry>
            <origin xyz="0 0 0" rpy="1.57 0 0"/>
            <material name="blue"/>
        </visual>
        <collision>
            <geometry>
                <sphere radius="0.05"/>
            </geometry>
            <origin xyz="0 0 0" rpy="1.57 0 0"/>
            <material name="blue"/>
        </collision>

        <inertial>
            <mass value="0.08"/> <!-- Mass of the caster wheel -->
            <origin xyz="0 0 0" rpy="0 0 0"/> <!-- Origin of the inertial frame -->
            <inertia>
                <ixx value="0.0000001"/> <!-- Inertia about the x-axis -->
                <iyy value="0.0000001"/> <!-- Inertia about the y-axis -->
                <izz value="0.00000024"/> <!-- Inertia about the z-axis -->
                <ixy value="0.0"/>      <!-- Product of inertia xy -->
                <ixz value="0.0"/>      <!-- Product of inertia xz -->
                <iyz value="0.0"/>      <!-- Product of inertia yz -->
            </inertia>
        </inertial>
    </link>
    
    <joint name="body_caster_wheel_joint2" type="fixed">
        <parent link="base_link"/>
        <child link="caster_wheel2"/>
        <origin xyz="-0.3 0 -0.05" rpy="0 0 0"/>
    </joint>



<!--supporint rod-->
    <link name="support_rod">
        <visual>
            <geometry>
                <box size="0.1 0.1 1.07" />
            </geometry>
            <material name="LightGrey">
                <color rgba="0.7 0.7 0.7 1.0"/>
            </material>
        </visual>
        <collision>
            <geometry>
                <box size="0.1 0.1 1.07" />
            </geometry>
        </collision>

        <inertial>
            <mass value="1.0"/> <!-- Mass of the support rod -->
            <origin xyz="0 0 0" rpy="0 0 0"/> <!-- Origin of the inertial frame -->
            <inertia>
                <ixx value="0.0045"/> <!-- Inertia about the x-axis -->
                <iyy value="0.0045"/> <!-- Inertia about the y-axis -->
                <izz value="0.03333"/> <!-- Inertia about the z-axis -->
                <ixy value="0.0"/>      <!-- Product of inertia xy -->
                <ixz value="0.0"/>      <!-- Product of inertia xz -->
                <iyz value="0.0"/>      <!-- Product of inertia yz -->
            </inertia>
        </inertial>
    </link>

    <joint name="base_suppot_joint" type="fixed">
        <origin xyz="-0.35 0. 0.835" rpy="0.0 0.0 0.0"/>
        <parent link="base_link"/>
        <child link="support_rod"/>
        <limit lower="0.0" upper="0.0" effort="0.0" velocity="0.0"/>
    </joint>


<!--u1-->
    <link name="u1">
        <visual>
            <geometry>
                <box size="0.6 0.1 0.04" />
            </geometry>
            <material name="black">
                <color rgba="0 0 0 1"/>
            </material>
        </visual>
        <collision>
            <geometry>
                <box size="0.6 0.1 0.04" />
            </geometry>
        </collision>

        <inertial>
            <mass value="0.3"/> <!-- Mass of the box -->
            <origin xyz="0 0 0" rpy="0 0 0"/> <!-- Origin of the inertial frame -->
            <inertia>
                <ixx value="0.0001"/> <!-- Inertia about the x-axis -->
                <iyy value="0.00933"/> <!-- Inertia about the y-axis -->
                <izz value="0.0451"/> <!-- Inertia about the z-axis -->
                <ixy value="0.0"/>      <!-- Product of inertia xy -->
                <ixz value="0.0"/>      <!-- Product of inertia xz -->
                <iyz value="0.0"/>      <!-- Product of inertia yz -->
            </inertia>
        </inertial>

    </link>

    <joint name="u1" type="fixed">
        <origin xyz="0 0 0.555" rpy="0.0 0.0 1.57"/>
        <parent link="support_rod"/>
        <child link="u1"/>
        <limit lower="0.0" upper="0.0" effort="0.0" velocity="0.0"/>
    </joint>

<!--u2-->
    
    <link name="u2">
        <visual>
            <geometry>
                <box size="0.6 0.1 0.04" />
            </geometry>
            <material name="black">
                <color rgba="0 0 0 1"/>
            </material>
        </visual>
        <collision>
            <geometry>
                <box size="0.6 0.1 0.04" />
            </geometry>
        </collision>

        <inertial>
            <mass value="0.3"/> <!-- Mass of the box -->
            <origin xyz="0 0 0" rpy="0 0 0"/> <!-- Origin of the inertial frame -->
            <inertia>
                <ixx value="0.0001"/> <!-- Inertia about the x-axis -->
                <iyy value="0.00933"/> <!-- Inertia about the y-axis -->
                <izz value="0.0451"/> <!-- Inertia about the z-axis -->
                <ixy value="0.0"/>      <!-- Product of inertia xy -->
                <ixz value="0.0"/>      <!-- Product of inertia xz -->
                <iyz value="0.0"/>      <!-- Product of inertia yz -->
            </inertia>
        </inertial>

    </link>

    <joint name="u2" type="fixed">
        <origin xyz="0.25 0.35 0.555" rpy="0.0 0.0 0"/>
        <parent link="support_rod"/>
        <child link="u2"/>
        <limit lower="0.0" upper="0.0" effort="0.0" velocity="0.0"/>
    </joint>    


<!--u3-->
    
    <link name="u3">
        <visual>
            <geometry>
                <box size="0.6 0.1 0.04" />
            </geometry>
            <material name="black">
                <color rgba="0 0 0 1"/>
            </material>
        </visual>
        <collision>
            <geometry>
                <box size="0.6 0.1 0.04" />
            </geometry>
        </collision>

        <inertial>
            <mass value="0.3"/> <!-- Mass of the box -->
            <origin xyz="0 0 0" rpy="0 0 0"/> <!-- Origin of the inertial frame -->
            <inertia>
                <ixx value="0.0001"/> <!-- Inertia about the x-axis -->
                <iyy value="0.00933"/> <!-- Inertia about the y-axis -->
                <izz value="0.0451"/> <!-- Inertia about the z-axis -->
                <ixy value="0.0"/>      <!-- Product of inertia xy -->
                <ixz value="0.0"/>      <!-- Product of inertia xz -->
                <iyz value="0.0"/>      <!-- Product of inertia yz -->
            </inertia>
        </inertial>
    </link>

    <joint name="u3" type="fixed">
        <origin xyz="0.25 -0.35 0.555" rpy="0.0 0.0 0"/>
        <parent link="support_rod"/>
        <child link="u3"/>
        <limit lower="0.0" upper="0.0" effort="0.0" velocity="0.0"/>
    </joint>

<!--tray-->
    <link name="tray">
        <visual>
            <origin xyz="0.0 0.0 0.0" rpy="0.0 0.0 0.0"/>
            <geometry>
                <box size="0.65 0.8 0.01"/>
            </geometry>
            <material name="white">
                <color rgba="1.0 1.0 1.0 1.0"/>
            </material>
        </visual>
        <collision>
            <origin xyz="0.0 0.0 0.0" rpy="0.0 0.0 0.0"/>
            <geometry>
                <box size="0.65 0.8 0.01"/>
            </geometry>
        </collision>

        <inertial>
            <mass value="0.5"/> <!-- Mass of the box -->
            <origin xyz="0 0 0" rpy="0 0 0"/> <!-- Origin of the inertial frame -->
            <inertia>
                <ixx value="0.0138"/> <!-- Inertia about the x-axis -->
                <iyy value="0.00845"/> <!-- Inertia about the y-axis -->
                <izz value="0.00000729"/> <!-- Inertia about the z-axis -->
                <ixy value="0.0"/>      <!-- Product of inertia xy -->
                <ixz value="0.0"/>      <!-- Product of inertia xz -->
                <iyz value="0.0"/>      <!-- Product of inertia yz -->
            </inertia>
        </inertial>

    </link>

    <joint name="joint_name" type="fixed">
        <origin xyz="0.375 0.0 -0.465" rpy="0.0 0.0 0.0"/>
        <parent link="support_rod"/>
        <child link="tray"/>
        <limit lower="0.0" upper="0.0" effort="0.0" velocity="0.0"/>
    </joint>
</robot>
 

 